inputs.image_id,outputs.output,error,feedback.exact_match,execution_time,example_id,id,output
84875,,"ResourceExhausted(""Gemini 2.5 Pro Preview doesn't have a free quota tier. Please use Gemini 2.5 Pro Experimental (models/gemini-2.5-pro-exp-03-25) instead. For more information on this error, head to: https://ai.google.dev/gemini-api/docs/rate-limits."")

Traceback (most recent call last):
  File ""/Users/mohamedgomaa/Downloads/Maids/LLM_passport_info/main.py"", line 72, in target
    return llm_chain_factory().invoke(formatted_inputs)
           ^^^^^^^^^^^^^^^^^^^^^^^^^^^^^^^^^^^^^^^^^^^^
  File ""/usr/local/anaconda3/lib/python3.11/site-packages/langchain_core/runnables/base.py"", line 3034, in invoke
    input = context.run(step.invoke, input, config)
            ^^^^^^^^^^^^^^^^^^^^^^^^^^^^^^^^^^^^^^^
  File ""/usr/local/anaconda3/lib/python3.11/site-packages/langchain_google_genai/chat_models.py"", line 1175, in invoke
    return super().invoke(input, config, stop=stop, **kwargs)
           ^^^^^^^^^^^^^^^^^^^^^^^^^^^^^^^^^^^^^^^^^^^^^^^^^^
  File ""/usr/local/anaconda3/lib/python3.11/site-packages/langchain_core/language_models/chat_models.py"", line 368, in invoke
    self.generate_prompt(
  File ""/usr/local/anaconda3/lib/python3.11/site-packages/langchain_core/language_models/chat_models.py"", line 937, in generate_prompt
    return self.generate(prompt_messages, stop=stop, callbacks=callbacks, **kwargs)
           ^^^^^^^^^^^^^^^^^^^^^^^^^^^^^^^^^^^^^^^^^^^^^^^^^^^^^^^^^^^^^^^^^^^^^^^^
  File ""/usr/local/anaconda3/lib/python3.11/site-packages/langchain_core/language_models/chat_models.py"", line 759, in generate
    self._generate_with_cache(
  File ""/usr/local/anaconda3/lib/python3.11/site-packages/langchain_core/language_models/chat_models.py"", line 1002, in _generate_with_cache
    result = self._generate(
             ^^^^^^^^^^^^^^^
  File ""/usr/local/anaconda3/lib/python3.11/site-packages/langchain_google_genai/chat_models.py"", line 1242, in _generate
    response: GenerateContentResponse = _chat_with_retry(
                                        ^^^^^^^^^^^^^^^^^
  File ""/usr/local/anaconda3/lib/python3.11/site-packages/langchain_google_genai/chat_models.py"", line 208, in _chat_with_retry
    return _chat_with_retry(**kwargs)
           ^^^^^^^^^^^^^^^^^^^^^^^^^^
  File ""/usr/local/anaconda3/lib/python3.11/site-packages/tenacity/__init__.py"", line 289, in wrapped_f
    return self(f, *args, **kw)
           ^^^^^^^^^^^^^^^^^^^^
  File ""/usr/local/anaconda3/lib/python3.11/site-packages/tenacity/__init__.py"", line 379, in __call__
    do = self.iter(retry_state=retry_state)
         ^^^^^^^^^^^^^^^^^^^^^^^^^^^^^^^^^^
  File ""/usr/local/anaconda3/lib/python3.11/site-packages/tenacity/__init__.py"", line 325, in iter
    raise retry_exc.reraise()
          ^^^^^^^^^^^^^^^^^^^
  File ""/usr/local/anaconda3/lib/python3.11/site-packages/tenacity/__init__.py"", line 158, in reraise
    raise self.last_attempt.result()
          ^^^^^^^^^^^^^^^^^^^^^^^^^^
  File ""/usr/local/anaconda3/lib/python3.11/concurrent/futures/_base.py"", line 449, in result
    return self.__get_result()
           ^^^^^^^^^^^^^^^^^^^
  File ""/usr/local/anaconda3/lib/python3.11/concurrent/futures/_base.py"", line 401, in __get_result
    raise self._exception
  File ""/usr/local/anaconda3/lib/python3.11/site-packages/tenacity/__init__.py"", line 382, in __call__
    result = fn(*args, **kwargs)
             ^^^^^^^^^^^^^^^^^^^
  File ""/usr/local/anaconda3/lib/python3.11/site-packages/langchain_google_genai/chat_models.py"", line 206, in _chat_with_retry
    raise e
  File ""/usr/local/anaconda3/lib/python3.11/site-packages/langchain_google_genai/chat_models.py"", line 190, in _chat_with_retry
    return generation_method(**kwargs)
           ^^^^^^^^^^^^^^^^^^^^^^^^^^^
  File ""/usr/local/anaconda3/lib/python3.11/site-packages/google/ai/generativelanguage_v1beta/services/generative_service/client.py"", line 867, in generate_content
    response = rpc(
               ^^^^
  File ""/usr/local/anaconda3/lib/python3.11/site-packages/google/api_core/gapic_v1/method.py"", line 131, in __call__
    return wrapped_func(*args, **kwargs)
           ^^^^^^^^^^^^^^^^^^^^^^^^^^^^^
  File ""/usr/local/anaconda3/lib/python3.11/site-packages/google/api_core/retry/retry_unary.py"", line 293, in retry_wrapped_func
    return retry_target(
           ^^^^^^^^^^^^^
  File ""/usr/local/anaconda3/lib/python3.11/site-packages/google/api_core/retry/retry_unary.py"", line 153, in retry_target
    _retry_error_helper(
  File ""/usr/local/anaconda3/lib/python3.11/site-packages/google/api_core/retry/retry_base.py"", line 212, in _retry_error_helper
    raise final_exc from source_exc
  File ""/usr/local/anaconda3/lib/python3.11/site-packages/google/api_core/retry/retry_unary.py"", line 144, in retry_target
    result = target()
             ^^^^^^^^
  File ""/usr/local/anaconda3/lib/python3.11/site-packages/google/api_core/timeout.py"", line 130, in func_with_timeout
    return func(*args, **kwargs)
           ^^^^^^^^^^^^^^^^^^^^^
  File ""/usr/local/anaconda3/lib/python3.11/site-packages/google/api_core/grpc_helpers.py"", line 78, in error_remapped_callable
    raise exceptions.from_grpc_error(exc) from exc
google.api_core.exceptions.ResourceExhausted: 429 Gemini 2.5 Pro Preview doesn't have a free quota tier. Please use Gemini 2.5 Pro Experimental (models/gemini-2.5-pro-exp-03-25) instead. For more information on this error, head to: https://ai.google.dev/gemini-api/docs/rate-limits. [violations {
  quota_metric: ""generativelanguage.googleapis.com/generate_content_free_tier_requests""
  quota_id: ""GenerateRequestsPerDayPerProjectPerModel-FreeTier""
  quota_dimensions {
    key: ""model""
    value: ""gemini-2.5-pro-exp""
  }
  quota_dimensions {
    key: ""location""
    value: ""global""
  }
}
violations {
  quota_metric: ""generativelanguage.googleapis.com/generate_content_free_tier_requests""
  quota_id: ""GenerateRequestsPerMinutePerProjectPerModel-FreeTier""
  quota_dimensions {
    key: ""model""
    value: ""gemini-2.5-pro-exp""
  }
  quota_dimensions {
    key: ""location""
    value: ""global""
  }
}
violations {
  quota_metric: ""generativelanguage.googleapis.com/generate_content_free_tier_input_token_count""
  quota_id: ""GenerateContentInputTokensPerModelPerMinute-FreeTier""
  quota_dimensions {
    key: ""model""
    value: ""gemini-2.5-pro-exp""
  }
  quota_dimensions {
    key: ""location""
    value: ""global""
  }
}
violations {
  quota_metric: ""generativelanguage.googleapis.com/generate_content_free_tier_input_token_count""
  quota_id: ""GenerateContentInputTokensPerModelPerDay-FreeTier""
  quota_dimensions {
    key: ""model""
    value: ""gemini-2.5-pro-exp""
  }
  quota_dimensions {
    key: ""location""
    value: ""global""
  }
}
, links {
  description: ""Learn more about Gemini API quotas""
  url: ""https://ai.google.dev/gemini-api/docs/rate-limits""
}
, retry_delay {
  seconds: 47
}
]
",False,5.728781,a6894c06-0103-4efc-9b99-425474ed0cb8,0d391654-49a1-42a5-a66a-4112d432f3f5,"{""output"": null}"
82842,,"ResourceExhausted(""Gemini 2.5 Pro Preview doesn't have a free quota tier. Please use Gemini 2.5 Pro Experimental (models/gemini-2.5-pro-exp-03-25) instead. For more information on this error, head to: https://ai.google.dev/gemini-api/docs/rate-limits."")

Traceback (most recent call last):
  File ""/Users/mohamedgomaa/Downloads/Maids/LLM_passport_info/main.py"", line 72, in target
    return llm_chain_factory().invoke(formatted_inputs)
           ^^^^^^^^^^^^^^^^^^^^^^^^^^^^^^^^^^^^^^^^^^^^
  File ""/usr/local/anaconda3/lib/python3.11/site-packages/langchain_core/runnables/base.py"", line 3034, in invoke
    input = context.run(step.invoke, input, config)
            ^^^^^^^^^^^^^^^^^^^^^^^^^^^^^^^^^^^^^^^
  File ""/usr/local/anaconda3/lib/python3.11/site-packages/langchain_google_genai/chat_models.py"", line 1175, in invoke
    return super().invoke(input, config, stop=stop, **kwargs)
           ^^^^^^^^^^^^^^^^^^^^^^^^^^^^^^^^^^^^^^^^^^^^^^^^^^
  File ""/usr/local/anaconda3/lib/python3.11/site-packages/langchain_core/language_models/chat_models.py"", line 368, in invoke
    self.generate_prompt(
  File ""/usr/local/anaconda3/lib/python3.11/site-packages/langchain_core/language_models/chat_models.py"", line 937, in generate_prompt
    return self.generate(prompt_messages, stop=stop, callbacks=callbacks, **kwargs)
           ^^^^^^^^^^^^^^^^^^^^^^^^^^^^^^^^^^^^^^^^^^^^^^^^^^^^^^^^^^^^^^^^^^^^^^^^
  File ""/usr/local/anaconda3/lib/python3.11/site-packages/langchain_core/language_models/chat_models.py"", line 759, in generate
    self._generate_with_cache(
  File ""/usr/local/anaconda3/lib/python3.11/site-packages/langchain_core/language_models/chat_models.py"", line 1002, in _generate_with_cache
    result = self._generate(
             ^^^^^^^^^^^^^^^
  File ""/usr/local/anaconda3/lib/python3.11/site-packages/langchain_google_genai/chat_models.py"", line 1242, in _generate
    response: GenerateContentResponse = _chat_with_retry(
                                        ^^^^^^^^^^^^^^^^^
  File ""/usr/local/anaconda3/lib/python3.11/site-packages/langchain_google_genai/chat_models.py"", line 208, in _chat_with_retry
    return _chat_with_retry(**kwargs)
           ^^^^^^^^^^^^^^^^^^^^^^^^^^
  File ""/usr/local/anaconda3/lib/python3.11/site-packages/tenacity/__init__.py"", line 289, in wrapped_f
    return self(f, *args, **kw)
           ^^^^^^^^^^^^^^^^^^^^
  File ""/usr/local/anaconda3/lib/python3.11/site-packages/tenacity/__init__.py"", line 379, in __call__
    do = self.iter(retry_state=retry_state)
         ^^^^^^^^^^^^^^^^^^^^^^^^^^^^^^^^^^
  File ""/usr/local/anaconda3/lib/python3.11/site-packages/tenacity/__init__.py"", line 325, in iter
    raise retry_exc.reraise()
          ^^^^^^^^^^^^^^^^^^^
  File ""/usr/local/anaconda3/lib/python3.11/site-packages/tenacity/__init__.py"", line 158, in reraise
    raise self.last_attempt.result()
          ^^^^^^^^^^^^^^^^^^^^^^^^^^
  File ""/usr/local/anaconda3/lib/python3.11/concurrent/futures/_base.py"", line 449, in result
    return self.__get_result()
           ^^^^^^^^^^^^^^^^^^^
  File ""/usr/local/anaconda3/lib/python3.11/concurrent/futures/_base.py"", line 401, in __get_result
    raise self._exception
  File ""/usr/local/anaconda3/lib/python3.11/site-packages/tenacity/__init__.py"", line 382, in __call__
    result = fn(*args, **kwargs)
             ^^^^^^^^^^^^^^^^^^^
  File ""/usr/local/anaconda3/lib/python3.11/site-packages/langchain_google_genai/chat_models.py"", line 206, in _chat_with_retry
    raise e
  File ""/usr/local/anaconda3/lib/python3.11/site-packages/langchain_google_genai/chat_models.py"", line 190, in _chat_with_retry
    return generation_method(**kwargs)
           ^^^^^^^^^^^^^^^^^^^^^^^^^^^
  File ""/usr/local/anaconda3/lib/python3.11/site-packages/google/ai/generativelanguage_v1beta/services/generative_service/client.py"", line 867, in generate_content
    response = rpc(
               ^^^^
  File ""/usr/local/anaconda3/lib/python3.11/site-packages/google/api_core/gapic_v1/method.py"", line 131, in __call__
    return wrapped_func(*args, **kwargs)
           ^^^^^^^^^^^^^^^^^^^^^^^^^^^^^
  File ""/usr/local/anaconda3/lib/python3.11/site-packages/google/api_core/retry/retry_unary.py"", line 293, in retry_wrapped_func
    return retry_target(
           ^^^^^^^^^^^^^
  File ""/usr/local/anaconda3/lib/python3.11/site-packages/google/api_core/retry/retry_unary.py"", line 153, in retry_target
    _retry_error_helper(
  File ""/usr/local/anaconda3/lib/python3.11/site-packages/google/api_core/retry/retry_base.py"", line 212, in _retry_error_helper
    raise final_exc from source_exc
  File ""/usr/local/anaconda3/lib/python3.11/site-packages/google/api_core/retry/retry_unary.py"", line 144, in retry_target
    result = target()
             ^^^^^^^^
  File ""/usr/local/anaconda3/lib/python3.11/site-packages/google/api_core/timeout.py"", line 130, in func_with_timeout
    return func(*args, **kwargs)
           ^^^^^^^^^^^^^^^^^^^^^
  File ""/usr/local/anaconda3/lib/python3.11/site-packages/google/api_core/grpc_helpers.py"", line 78, in error_remapped_callable
    raise exceptions.from_grpc_error(exc) from exc
google.api_core.exceptions.ResourceExhausted: 429 Gemini 2.5 Pro Preview doesn't have a free quota tier. Please use Gemini 2.5 Pro Experimental (models/gemini-2.5-pro-exp-03-25) instead. For more information on this error, head to: https://ai.google.dev/gemini-api/docs/rate-limits. [violations {
  quota_metric: ""generativelanguage.googleapis.com/generate_content_free_tier_requests""
  quota_id: ""GenerateRequestsPerDayPerProjectPerModel-FreeTier""
  quota_dimensions {
    key: ""model""
    value: ""gemini-2.5-pro-exp""
  }
  quota_dimensions {
    key: ""location""
    value: ""global""
  }
}
violations {
  quota_metric: ""generativelanguage.googleapis.com/generate_content_free_tier_requests""
  quota_id: ""GenerateRequestsPerMinutePerProjectPerModel-FreeTier""
  quota_dimensions {
    key: ""model""
    value: ""gemini-2.5-pro-exp""
  }
  quota_dimensions {
    key: ""location""
    value: ""global""
  }
}
violations {
  quota_metric: ""generativelanguage.googleapis.com/generate_content_free_tier_input_token_count""
  quota_id: ""GenerateContentInputTokensPerModelPerMinute-FreeTier""
  quota_dimensions {
    key: ""model""
    value: ""gemini-2.5-pro-exp""
  }
  quota_dimensions {
    key: ""location""
    value: ""global""
  }
}
violations {
  quota_metric: ""generativelanguage.googleapis.com/generate_content_free_tier_input_token_count""
  quota_id: ""GenerateContentInputTokensPerModelPerDay-FreeTier""
  quota_dimensions {
    key: ""model""
    value: ""gemini-2.5-pro-exp""
  }
  quota_dimensions {
    key: ""location""
    value: ""global""
  }
}
, links {
  description: ""Learn more about Gemini API quotas""
  url: ""https://ai.google.dev/gemini-api/docs/rate-limits""
}
, retry_delay {
  seconds: 43
}
]
",False,4.024658,cb1d62f6-0075-488b-8e5f-10d1a6ecb32b,ceda11c6-d7f0-46c2-9129-acd595253bc1,"{""output"": null}"
