inputs.image_id,outputs.output,error,reference.reference_output,feedback.field_match,feedback.full_passport,execution_time,example_id,id,output
87578,,"ValueError(""Invalid input type <class 'langchain_core.messages.human.HumanMessage'>. Must be a PromptValue, str, or list of BaseMessages."")

Traceback (most recent call last):
  File ""/Users/mohamedgomaa/Downloads/Maids/LLM_passport_info/main.py"", line 158, in target
    results = llm_chain_factory().invoke(formatted_inputs)
              ^^^^^^^^^^^^^^^^^^^^^^^^^^^^^^^^^^^^^^^^^^^^
  File ""/usr/local/anaconda3/lib/python3.11/site-packages/langchain_core/runnables/base.py"", line 3034, in invoke
    input = context.run(step.invoke, input, config)
            ^^^^^^^^^^^^^^^^^^^^^^^^^^^^^^^^^^^^^^^
  File ""/usr/local/anaconda3/lib/python3.11/site-packages/langchain_core/runnables/retry.py"", line 201, in invoke
    return self._call_with_config(self._invoke, input, config, **kwargs)
           ^^^^^^^^^^^^^^^^^^^^^^^^^^^^^^^^^^^^^^^^^^^^^^^^^^^^^^^^^^^^^
  File ""/usr/local/anaconda3/lib/python3.11/site-packages/langchain_core/runnables/base.py"", line 1930, in _call_with_config
    context.run(
  File ""/usr/local/anaconda3/lib/python3.11/site-packages/langchain_core/runnables/config.py"", line 428, in call_func_with_variable_args
    return func(input, **kwargs)  # type: ignore[call-arg]
           ^^^^^^^^^^^^^^^^^^^^^
  File ""/usr/local/anaconda3/lib/python3.11/site-packages/langchain_core/runnables/retry.py"", line 186, in _invoke
    for attempt in self._sync_retrying(reraise=True):
  File ""/usr/local/anaconda3/lib/python3.11/site-packages/tenacity/__init__.py"", line 347, in __iter__
    do = self.iter(retry_state=retry_state)
         ^^^^^^^^^^^^^^^^^^^^^^^^^^^^^^^^^^
  File ""/usr/local/anaconda3/lib/python3.11/site-packages/tenacity/__init__.py"", line 325, in iter
    raise retry_exc.reraise()
          ^^^^^^^^^^^^^^^^^^^
  File ""/usr/local/anaconda3/lib/python3.11/site-packages/tenacity/__init__.py"", line 158, in reraise
    raise self.last_attempt.result()
          ^^^^^^^^^^^^^^^^^^^^^^^^^^
  File ""/usr/local/anaconda3/lib/python3.11/concurrent/futures/_base.py"", line 449, in result
    return self.__get_result()
           ^^^^^^^^^^^^^^^^^^^
  File ""/usr/local/anaconda3/lib/python3.11/concurrent/futures/_base.py"", line 401, in __get_result
    raise self._exception
  File ""/usr/local/anaconda3/lib/python3.11/site-packages/langchain_core/runnables/retry.py"", line 188, in _invoke
    result = super().invoke(
             ^^^^^^^^^^^^^^^
  File ""/usr/local/anaconda3/lib/python3.11/site-packages/langchain_core/runnables/base.py"", line 5416, in invoke
    return self.bound.invoke(
           ^^^^^^^^^^^^^^^^^^
  File ""/usr/local/anaconda3/lib/python3.11/site-packages/langchain_core/language_models/chat_models.py"", line 369, in invoke
    [self._convert_input(input)],
     ^^^^^^^^^^^^^^^^^^^^^^^^^^
  File ""/usr/local/anaconda3/lib/python3.11/site-packages/langchain_core/language_models/chat_models.py"", line 354, in _convert_input
    raise ValueError(msg)  # noqa: TRY004
    ^^^^^^^^^^^^^^^^^^^^^
ValueError: Invalid input type <class 'langchain_core.messages.human.HumanMessage'>. Must be a PromptValue, str, or list of BaseMessages.
","{'gender': 'FEMALE', 'birthdate': '1980-01-13', 'last name': 'RICAFORT', 'first name': 'CRISTINA', 'birth place': 'TACURONG S KUD', 'middle name': 'ASIS', 'mother name': 'ASIS', 'nationality': 'FILIPINA', 'passport id': 'P1309514B', 'country of issue': 'CHINA', 'passport place(en)': 'PCG HONG KONG', 'passport issue date': '2019-04-02', 'passport expiry date': '2029-04-01'}",0,False,17.698019,18630479-4ae8-42bd-806d-9b010d543358,a188dca6-1448-40a3-9b6b-a7df7b5ec287,"{""output"": null}"
